#VRML_SIM R2021a utf8
WorldInfo {
  contactProperties [
    ContactProperties {
      material1 "ExteriorWheelMat"
      coulombFriction [
        1.8, 0, 0.2
      ]
      frictionRotation 0.965 0
      forceDependentSlip [
        10, 0
      ]
    }
    ContactProperties {
      material1 "InteriorWheelMat"
      coulombFriction [
        1.8, 0, 0.2
      ]
      frictionRotation -0.965 0
      forceDependentSlip [
        10, 0
      ]
    }
  ]
}
Viewpoint {
  orientation 0.5144899428834944 0.0032156040126506127 0.8574903839475825 0.014577354615005776
  position 0.0023729836931300546 -0.18488778698772798 24.67586035474172
  follow "car4"
  followType "None"
}
TexturedBackground {
}
TexturedBackgroundLight {
}
RectangleArena {
  rotation 1 0 0 1.5708
  floorSize 10 10
}
DEF Supervisor Robot {
  controller "openDoor"
  supervisor TRUE
}
DEF DOOR1 Door {
  translation -2.5 -4.25 0
  rotation 0.5773509358554485 0.5773489358556708 0.5773509358554485 2.0944
  name "door1"
  size 1.5 2.4 0.2
  position -1.570000000340288
}
DEF DOOR2 Door {
  translation -1.125 2.75 0
  rotation 1 0 0 1.5708
  name "door2"
  size 1.25 2.4 0.2
  position -4.397212286874799e-08
}
Wall {
  translation -4 -2.75 1.23289e-06
  rotation 0.5773509358554485 0.5773489358556708 0.5773509358554485 2.0944
  size 2.5 2 0.1
}
Wall {
  translation -3.25 -1.5 0
  rotation 1 0 0 1.5708
  name "wall(1)"
  size 1.5 2 0.1
}
Wall {
  translation -2.5 -2.5 0
  rotation 0.5773509358554485 0.5773489358556708 0.5773509358554485 2.0944
  name "wall(2)"
  size 2 2 0.1
}
Wall {
  translation -1 -3 0
  rotation 1 0 0 1.5708
  name "wall(4)"
  size 3 2 0.1
}
Wall {
  translation 0 -1.5 0
  rotation 1.6952594753969508e-09 0.707104781184338 0.7071087811831002 -3.1415853071795863
  name "wall(7)"
  size 3 2 0.1
}
Wall {
  translation 2 3.75 0
  rotation 1.6952594753969508e-09 0.707104781184338 0.7071087811831002 -3.1415853071795863
  name "wall(8)"
  size 2 2 0.1
}
Wall {
  translation 4 2.75 0
  rotation 1.6952594753969508e-09 0.707104781184338 0.7071087811831002 -3.1415853071795863
  name "wall(9)"
  size 2 2 0.1
}
Wall {
  translation 0.5 2.75 0
  rotation 1.6952594753969508e-09 0.707104781184338 0.7071087811831002 -3.1415853071795863
  name "wall(11)"
  size 2 2 0.1
}
Wall {
  translation 3 3.25 0
  rotation 0.5773509358554485 0.5773489358556708 0.5773509358554485 2.0944
  name "wall(12)"
  size 1 2 0.1
}
Wall {
  translation 2.5 1.25 0
  rotation 1.6952594753969508e-09 0.707104781184338 0.7071087811831002 -3.1415853071795863
  name "wall(13)"
  size 2 2 0.1
}
Wall {
  translation 1.5 -0.5 0
  rotation 0.5773509358554485 0.5773489358556708 0.5773509358554485 2.0944
  name "wall(14)"
  size 6.5 2 0.1
}
Wall {
  translation 2.5 -3.75 0
  rotation 1.6952594753969508e-09 0.707104781184338 0.7071087811831002 -3.1415853071795863
  name "wall(15)"
  size 2 2 0.1
}
Wall {
  translation 3.5 -2.75 0
  rotation 0.5773509358554485 0.5773489358556708 0.5773509358554485 2.0944
  name "wall(16)"
  size 2 2 0.1
}
Wall {
  translation 4 -0.25 0
  rotation 1.6952594753969508e-09 0.707104781184338 0.7071087811831002 -3.1415853071795863
  name "wall(21)"
  size 2 2 0.1
}
DEF car4 Robot {
  translation 4.5 4.5 0.0480467
  rotation 0.5773452691693968 0.5773492691712616 0.5773562691745252 2.09441
  children [
    InertialUnit {
      rotation -0.5772162380336358 0.5772162380336358 0.5776182381994135 2.09399
    }
    Lidar {
      translation 0 0.14 0
      rotation 0 1 0 1.5701
      horizontalResolution 1024
      fieldOfView 6.28
      verticalFieldOfView 0.05
      numberOfLayers 1
      near 0.001
      minRange 0.05
      maxRange 7
    }
    Display {
      width 100
      height 100
    }
    GPS {
    }
    DEF fld HingeJoint {
      jointParameters HingeJointParameters {
        axis 0 1 0
        anchor -0.04 0 -0.04
      }
      device [
        RotationalMotor {
          name "fld"
        }
      ]
      endPoint Solid {
        children [
          DEF fle Transform {
            translation -0.04 0 -0.04
            children [
              Shape {
                appearance PBRAppearance {
                  transparency 0.5
                }
                geometry Cylinder {
                  height 0.01
                  radius 0.01
                }
              }
            ]
          }
          DEF fl HingeJoint {
            jointParameters HingeJointParameters {
              position -7.363933463011563e-09
              axis -1 0 0
              anchor -0.04 -0.02 -0.04
            }
            device [
              RotationalMotor {
                name "fl"
                consumptionFactor -0.001
                maxVelocity 100
              }
            ]
            endPoint DEF WHEEL1 Solid {
              translation -0.04 -0.02 -0.04
              rotation -0.6740628889756072 0.673593684265515 0.30316789114856485 2.5524847194319453
              children [
                DEF WHEEL Shape {
                  appearance PBRAppearance {
                    baseColor 1 1 0
                  }
                  geometry Cylinder {
                    height 0.02
                    radius 0.02
                  }
                }
              ]
              name "solid(3)"
              contactMaterial "ExteriorWheelMat"
              boundingObject USE WHEEL
              physics DEF WHEEL_PH Physics {
                density -1
                mass 1
              }
            }
          }
        ]
        name "solid(3)"
        boundingObject USE fle
        physics Physics {
        }
      }
    }
    DEF frd HingeJoint {
      jointParameters HingeJointParameters {
        axis 0 1 0
        anchor 0.04 0 -0.04
      }
      device [
        RotationalMotor {
          name "frd"
        }
      ]
      endPoint Solid {
        children [
          DEF fre Transform {
            translation 0.04 0 -0.04
            children [
              Shape {
                appearance PBRAppearance {
                  transparency 0.5
                }
                geometry Cylinder {
                  height 0.01
                  radius 0.01
                }
              }
            ]
          }
          DEF fr HingeJoint {
            jointParameters HingeJointParameters {
              position -2.112277464050294e-09
              axis -1 0 0
              anchor 0.04 -0.02 -0.04
            }
            device [
              RotationalMotor {
                name "fr"
                consumptionFactor -0.001
                maxVelocity 100
              }
            ]
            endPoint DEF WHEEL1 Solid {
              translation 0.04 -0.02 -0.04
              rotation 0.6788109712882143 -0.6783384615117535 0.2811985008719253 2.5929901774749533
              children [
                DEF WHEEL Shape {
                  appearance PBRAppearance {
                    baseColor 1 1 0
                  }
                  geometry Cylinder {
                    height 0.02
                    radius 0.02
                  }
                }
              ]
              name "solid(2)"
              contactMaterial "InteriorWheelMat"
              boundingObject USE WHEEL
              physics DEF WHEEL_PH Physics {
                density -1
                mass 1
              }
            }
          }
        ]
        name "solid(4)"
        boundingObject DEF fre Transform {
          translation 0.04 0 -0.04
          children [
            Shape {
              appearance PBRAppearance {
                transparency 0.5
              }
              geometry Cylinder {
                height 0.01
                radius 0.01
              }
            }
          ]
        }
        physics Physics {
        }
      }
    }
    DEF hr HingeJoint {
      jointParameters HingeJointParameters {
        position -5.6059183961565395e-09
        axis -1 0 0
        anchor 0.04 -0.02 0.04
      }
      device [
        RotationalMotor {
          name "hr"
          consumptionFactor -0.001
          maxVelocity 100
        }
      ]
      endPoint DEF WHEEL1 Solid {
        translation 0.04 -0.02 0.04
        rotation 2.7306664529866722e-09 -2.7306763562754103e-09 0.9999999999999999 1.570799999995009
        children [
          DEF WHEEL Shape {
            appearance PBRAppearance {
              baseColor 1 1 0
            }
            geometry Cylinder {
              height 0.02
              radius 0.02
            }
          }
        ]
        name "solid(1)"
        contactMaterial "ExteriorWheelMat"
        boundingObject USE WHEEL
        physics DEF WHEEL_PH Physics {
          density -1
          mass 1
        }
      }
    }
    DEF hl HingeJoint {
      jointParameters HingeJointParameters {
        position 1.2444904357341072e-09
        axis -1 0 0
        anchor -0.04 -0.02 0.04
      }
      device [
        RotationalMotor {
          name "hl"
          consumptionFactor -0.001
          maxVelocity 100
        }
      ]
      endPoint DEF WHEEL1 Solid {
        translation -0.04 -0.02 0.04
        rotation -5.746213303837161e-10 5.746233804972645e-10 0.9999999999999999 1.570799999994974
        children [
          DEF WHEEL Shape {
            appearance PBRAppearance {
              baseColor 1 1 0
            }
            geometry Cylinder {
              height 0.02
              radius 0.02
            }
          }
        ]
        contactMaterial "InteriorWheelMat"
        boundingObject USE WHEEL
        physics DEF WHEEL_PH Physics {
          density -1
          mass 1
        }
      }
    }
    DEF BODY Shape {
      appearance PBRAppearance {
        baseColor 0.333333 0 1
      }
      geometry Box {
        size 0.05 0.05 0.08
      }
    }
  ]
  name "car4"
  model "robot"
  boundingObject USE BODY
  physics Physics {
    density -1
    mass 5
  }
  controller "my_controller_world3"
}
Wall {
  translation -2.25 0.5 0
  rotation 1.6952594753969508e-09 0.707104781184338 0.7071087811831002 -3.1415853071795863
  name "wall(22)"
  size 3.5 2 0.1
}
Wall {
  translation -1.75 3.5 0
  rotation 0.5773509358554485 0.5773489358556708 0.5773509358554485 2.0944
  name "wall(23)"
  size 3 2 0.1
}
Wall {
  translation -2.25 2 0
  rotation 1.6952594753969508e-09 0.707104781184338 0.7071087811831002 -3.1415853071795863
  name "wall(25)"
  size 1 2 0.1
}
Wall {
  translation -4 2.75 0
  rotation 0.5773509358554485 0.5773489358556708 0.5773509358554485 2.0944
  name "wall(26)"
  size 2 2 0.1
}
Wall {
  translation -4 3.75 0
  rotation 1.6952594753969508e-09 0.707104781184338 0.7071087811831002 -3.1415853071795863
  name "wall(27)"
  size 2 2 0.1
}
Wall {
  translation -4 0 0
  rotation 0.5773509358554485 0.5773489358556708 0.5773509358554485 2.0944
  name "wall(29)"
  size 1 2 0.1
}
